Workbook

Sheet gamesToAssign
A1: Age Group | B1: Date | C1: Time | D1: Venue | E1: Position | F1: Assigned | G1: Req1 | H1: Req2 | I1: Req3 | J1: Req4 | K1: Req5 | L1: Req6 | M1: Req7 | N1: Req8 | O1: Req9 | P1: Req10 | Q1: Req11 | R1: Req12 | S1: Req13 | T1: Req14 | U1: Req15 | V1: Req16 | W1: Req17 | X1: Req18 | Y1: Req19 | Z1: Req20
A2: Minors A | B2: May 1 2026 | C2: 0.75 | D2: Oak Park | E2: Plate Umpire | F2: McTaggart, Leo | G2: Fairweather, Cole | H2: Hatchard, Ethan | I2: Lopez, Hector | J2: McTaggart, Leo
A3: Minors A | B3: May 1 2026 | C3: 0.75 | D3: Oak Park | E3: Base Umpire | F3: Lopez, Hector | G3: Hatchard, Ethan | H3: McTaggart, Leo
A4: Minors B | B4: May 2 2026 | C4: 0.45833333 | D4: Challenger | E4: Plate Umpire | F4: Lee, Peyton | G4: Bayntun, Liam | H4: Douglas, James | I4: Fairweather, Cole | J4: Hatchard, Ethan | K4: Hiemstra, Sebastian | L4: Lee, Peyton | M4: MacDonald-Skala, Viggo | N4: Sandhu, Jordan | O4: Wong, Sam | P4: Zeck, Alex
A5: Minors B | B5: May 2 2026 | C5: 0.45833333 | D5: Challenger | E5: Base Umpire | F5: MacDonald-Skala, Viggo | G5: Bayntun, Liam | H5: Dolgin, Erez | I5: MacDonald-Skala, Viggo | J5: Stebbings, Colin | K5: Wong, Sam
A6: Minors B | B6: May 2 2026 | C6: 0.58333333 | D6: Challenger | E6: Plate Umpire | F6: Wong, Sam | G6: Bayntun, Liam | H6: Douglas, James | I6: Forbes, Sid | J6: Hatchard, Ethan | K6: Hiemstra, Sebastian | L6: MacDonald-Skala, Viggo | M6: Wong, Sam
A7: Minors B | B7: May 2 2026 | C7: 0.58333333 | D7: Challenger | E7: Base Umpire | F7: Dolgin, Erez | G7: Bayntun, Liam | H7: Dolgin, Erez | I7: MacDonald-Skala, Viggo | J7: Stebbings, Colin | K7: Wong, Sam
A8: Minors B | B8: May 2 2026 | C8: 0.70833333 | D8: Challenger | E8: Plate Umpire | F8: Rose, John | G8: Fairweather, Cole | H8: Hiemstra, Sebastian | I8: MacDonald-Skala, Viggo | J8: Rose, John | K8: Wong, Sam
A9: Minors B | B9: May 2 2026 | C9: 0.70833333 | D9: Challenger | E9: Base Umpire | F9: Stebbings, Colin | G9: MacDonald-Skala, Viggo | H9: Rose, John | I9: Stebbings, Colin | J9: Wong, Sam
A10: Minors B | B10: May 2 2026 | C10: 0.41666667 | D10: Columbia Park | E10: Plate Umpire | F10: Sandhu, Jordan | G10: Bayntun, Liam | H10: Fairweather, Cole | I10: Hatchard, Ethan | J10: Lopez, Hector | K10: MacDonald-Skala, Viggo | L10: Morrison, Oscar | M10: Sandhu, Jordan | N10: Wong, Sam
A11: Minors B | B11: May 2 2026 | C11: 0.41666667 | D11: Columbia Park | E11: Base Umpire | F11: Bayntun, Liam | G11: Bayntun, Liam | H11: Dolgin, Erez | I11: Lopez, Hector | J11: MacDonald-Skala, Viggo | K11: Wong, Sam
A12: Minors B | B12: May 2 2026 | C12: 0.54166667 | D12: Columbia Park | E12: Plate Umpire | F12: Morrison, Oscar | G12: Bayntun, Liam | H12: Hatchard, Ethan | I12: MacDonald-Skala, Viggo | J12: Morrison, Oscar | K12: Wong, Sam
A13: Minors B | B13: May 2 2026 | C13: 0.54166667 | D13: Columbia Park | E13: Base Umpire | F13: Dolgin, Erez | G13: Bayntun, Liam | H13: Dolgin, Erez | I13: MacDonald-Skala, Viggo | J13: Wong, Sam
A14: Minors B | B14: May 2 2026 | C14: 0.66666667 | D14: Columbia Park | E14: Plate Umpire | F14: McCulloch, Oswyn | G14: Fairweather, Cole | H14: Hatchard, Ethan | I14: Lee, Paul | J14: MacDonald-Skala, Viggo | K14: McCulloch, Oswyn | L14: Wong, Sam
A15: Minors B | B15: May 2 2026 | C15: 0.66666667 | D15: Columbia Park | E15: Base Umpire | F15: MacDonald-Skala, Viggo | G15: MacDonald-Skala, Viggo | H15: Wong, Sam
A16: Majors | B16: May 2 2026 | C16: 0.5 | D16: Hillcrest Park | E16: Plate Umpire | F16: Jordan Davis (not requested, but Assignr says he's available)
A17: Majors | B17: May 2 2026 | C17: 0.5 | D17: Hillcrest Park | E17: Base Umpire | F17: Douglas, James | G17: Bellefeuille, Nicholas | H17: Douglas, James | I17: Hatchard, Ethan
A18: Majors | B18: May 2 2026 | C18: 0.625 | D18: Hillcrest Park | E18: Plate Umpire | F18: Jordan Davis (not requested, but Assignr says he's available)
A19: Majors | B19: May 2 2026 | C19: 0.625 | D19: Hillcrest Park | E19: Base Umpire | F19: Bellefeuille, Nicholas | G19: Bellefeuille, Nicholas | H19: Douglas, James | I19: Hatchard, Ethan
A20: Majors | B20: May 2 2026 | C20: 0.75 | D20: Hillcrest Park | E20: Plate Umpire | F20: No requests (I can do this one)
A21: Majors | B21: May 2 2026 | C21: 0.75 | D21: Hillcrest Park | E21: Base Umpire | F21: Fairweather, Cole | G21: Bellefeuille, Nicholas | H21: Douglas, James | I21: Fairweather, Cole
A22: Minors B | B22: May 3 2026 | C22: 0.58333333 | D22: Challenger | E22: Plate Umpire | F22: Massel, Jacob | G22: Arai, Tatsuki | H22: Bayntun, Liam | I22: Black, Brooks | J22: Fairweather, Cole | K22: Lee, Paul | L22: MacDonald-Skala, Viggo | M22: Massel, Jacob | N22: McCulloch, Oswyn | O22: Milton, Rigel | P22: Morrison, Oscar | Q22: Ross, Connor | R22: Wong, Declan | S22: Zeck, Alex
A23: Minors B | B23: May 3 2026 | C23: 0.58333333 | D23: Challenger | E23: Base Umpire | F23: Pettersson, Oskar | G23: Arai, Tatsuki | H23: Bayntun, Liam | I23: Chuang, Kayden | J23: Dolgin, Erez | K23: Ferris, Easton | L23: Hiemstra, Sebastian | M23: MacDonald-Skala, Viggo | N23: Pettersson, Oskar | O23: Sato, Zain | P23: Stebbings, Colin | Q23: Wong, Declan
A24: Minors B | B24: May 3 2026 | C24: 0.70833333 | D24: Challenger | E24: Plate Umpire | F24: Ozaki, Jin | G24: Arai, Tatsuki | H24: Bayntun, Liam | I24: Fairweather, Cole | J24: MacDonald-Skala, Viggo | K24: McCulloch, Oswyn | L24: Morris, George | M24: Ozaki, Jin | N24: Rose, John | O24: Wong, Declan | P24: Zeck, Alex
A25: Minors B | B25: May 3 2026 | C25: 0.70833333 | D25: Challenger | E25: Base Umpire | F25: Sato, Zain | G25: Arai, Tatsuki | H25: Bayntun, Liam | I25: MacDonald-Skala, Viggo | J25: Pettersson, Oskar | K25: Rose, John | L25: Sato, Zain | M25: Stebbings, Colin | N25: Wong, Declan
A26: Minors B | B26: May 3 2026 | C26: 0.41666667 | D26: Columbia Park | E26: Plate Umpire | F26: Black, Brooks | G26: Arai, Tatsuki | H26: Bayntun, Liam | I26: Black, Brooks | J26: Fairweather, Cole | K26: Hatchard, Ethan | L26: MacDonald-Skala, Viggo | M26: Sandhu, Jordan | N26: Wong, Declan
A27: Minors B | B27: May 3 2026 | C27: 0.41666667 | D27: Columbia Park | E27: Base Umpire | F27: Arai, Tatsuki | G27: Arai, Tatsuki | H27: Bayntun, Liam | I27: Dolgin, Erez | J27: MacDonald-Skala, Viggo | K27: Stebbings, Colin | L27: Wong, Declan
A28: Minors A | B28: May 3 2026 | C28: 0.5 | D28: Hillcrest Park | E28: Plate Umpire | F28: Douglas, James | G28: Douglas, James | H28: Fairweather, Cole | I28: Forbes, Sid | J28: Hatchard, Ethan | K28: Huang, Daniel | L28: Lopez, Hector | M28: Suto, Sam
A29: Minors A | B29: May 3 2026 | C29: 0.5 | D29: Hillcrest Park | E29: Base Umpire | F29: Mah Ming, Matthew | G29: Bick, Jonathan (Yoni) | H29: Hatchard, Ethan | I29: Huang, Daniel | J29: Mah Ming, Matthew
A30: Minors A | B30: May 3 2026 | C30: 0.625 | D30: Hillcrest Park | E30: Plate Umpire | F30: Forbes, Sid | G30: Fairweather, Cole | H30: Forbes, Sid | I30: Huang, Daniel | J30: McTaggart, Leo | K30: Suto, Sam
A31: Minors A | B31: May 3 2026 | C31: 0.625 | D31: Hillcrest Park | E31: Base Umpire | F31: McTaggart, Leo | G31: Huang, Daniel | H31: McTaggart, Leo
A32: Minors A | B32: May 3 2026 | C32: 0.75 | D32: Hillcrest Park | E32: Plate Umpire | F32: Suto, Sam | G32: Fairweather, Cole | H32: Hatchard, Ethan | I32: Huang, Daniel | J32: Suto, Sam
A33: Minors A | B33: May 3 2026 | C33: 0.75 | D33: Hillcrest Park | E33: Base Umpire | F33: Huang, Daniel | G33: Hatchard, Ethan | H33: Huang, Daniel
A34: Minors A | B34: May 3 2026 | C34: 0.54166667 | D34: Oak Park | E34: Plate Umpire | F34: Fairweather, Cole | G34: Fairweather, Cole | H34: Huang, Daniel
A35: Minors A | B35: May 3 2026 | C35: 0.54166667 | D35: Oak Park | E35: Base Umpire | F35: Huang, Daniel | G35: Huang, Daniel
A36: Majors | B36: May 4 2026 | C36: 0.75 | D36: Hillcrest Park | E36: Plate Umpire | F36: Jackson, Caleb | G36: Froelich, Ari | H36: Hui, Sawyer | I36: Jackson, Caleb | J36: Meichenbaum, Reid | K36: Tsang, Aaron
A37: Majors | B37: May 4 2026 | C37: 0.75 | D37: Hillcrest Park | E37: Base Umpire | F37: Meichenbaum, Reid | G37: Froelich, Ari | H37: Hatchard, Ethan | I37: Meichenbaum, Reid
A38: Majors | B38: May 4 2026 | C38: 0.75 | D38: Oak Park | E38: Plate Umpire | F38: Froelich, Ari
A39: Majors | B39: May 4 2026 | C39: 0.75 | D39: Oak Park | E39: Base Umpire | F39: Tsang, Aaron
A40: Minors A | B40: May 5 2026 | C40: 0.75 | D40: Hillcrest Park | E40: Plate Umpire | F40: Waddell, Matthew | G40: Fairweather, Cole | H40: Hatchard, Ethan | I40: Lopez, Hector | J40: Waddell, Matthew
...

Sheet RequestCount
A1: Name | B1: AssignrId | C1: Requests made for this period | D1: Previous assignments | E1: Assigned games | F1: If 0 assignments, who was assigned to their requests?
A2: Hatchard, Ethan | B2: 1498680 | C2: 26 | D2: 9 | E2: =COUNTIF(gamesToAssign!F$2:'gamesToAssign'!F$51,A2) -> 3
A3: Fairweather, Cole | B3: 2122363 | C3: 19 | D3: 7 | E3: =COUNTIF(gamesToAssign!F$2:'gamesToAssign'!F$51,A3) -> 4
A4: Hui, Sawyer | B4: 904071 | C4: 1 | D4: 6 | E4: =COUNTIF(gamesToAssign!F$2:'gamesToAssign'!F$51,A4) -> 0 | F4: Caleb Jackson
A5: Douglas, James | B5: 1521201 | C5: 8 | D5: 6 | E5: =COUNTIF(gamesToAssign!F$2:'gamesToAssign'!F$51,A5) -> 3
A6: Waddell, Matthew | B6: 2127213 | C6: 1 | D6: 6 | E6: =COUNTIF(gamesToAssign!F$2:'gamesToAssign'!F$51,A6) -> 1
A7: Meichenbaum, Reid | B7: 962116 | C7: 3 | D7: 5 | E7: =COUNTIF(gamesToAssign!F$2:'gamesToAssign'!F$51,A7) -> 2
A8: Lopez, Hector | B8: 1499805 | C8: 9 | D8: 5 | E8: =COUNTIF(gamesToAssign!F$2:'gamesToAssign'!F$51,A8) -> 2
A9: McTaggart, Leo | B9: 1899180 | C9: 6 | D9: 4 | E9: =COUNTIF(gamesToAssign!F$2:'gamesToAssign'!F$51,A9) -> 3
A10: Suto, Sam | B10: 1899182 | C10: 3 | D10: 4 | E10: =COUNTIF(gamesToAssign!F$2:'gamesToAssign'!F$51,A10) -> 1
A11: Huang, Daniel | B11: 1899171 | C11: 8 | D11: 4 | E11: =COUNTIF(gamesToAssign!F$2:'gamesToAssign'!F$51,A11) -> 2
A12: Wong, Sam | B12: 2122385 | C12: 12 | D12: 3 | E12: =COUNTIF(gamesToAssign!F$2:'gamesToAssign'!F$51,A12) -> 1
A13: Sandhu, Jordan | B13: 2122379 | C13: 3 | D13: 3 | E13: =COUNTIF(gamesToAssign!F$2:'gamesToAssign'!F$51,A13) -> 1
A14: Zeck, Alex | B14: 2122386 | C14: 3 | D14: 3 | E14: =COUNTIF(gamesToAssign!F$2:'gamesToAssign'!F$51,A14) -> 0 | F14: Peyton Lee, Massel, Jacob, Osaki, Jin
A15: Lee, Paul | B15: 2112768 | C15: 2 | D15: 3 | E15: =COUNTIF(gamesToAssign!F$2:'gamesToAssign'!F$51,A15) -> 0 | F15: McCulloch, Oswyn, Arai, Tatsuki
A16: Bick, Jonathan (Yoni) | B16: 1899162 | C16: 2 | D16: 3 | E16: =COUNTIF(gamesToAssign!F$2:'gamesToAssign'!F$51,A16) -> 1
A17: Hiemstra, Sebastian | B17: 2122366 | C17: 4 | D17: 3 | E17: =COUNTIF(gamesToAssign!F$2:'gamesToAssign'!F$51,A17) -> 0 | F17: Lee, Peyton, Wong, Sam, Rose, John, Pettersson, Oskar
A18: Tsang, Aaron | B18: 961960 | C18: 1 | D18: 2 | E18: =COUNTIF(gamesToAssign!F$2:'gamesToAssign'!F$51,A18) -> 1
A19: Mah Ming, Matthew | B19: 1905146 | C19: 1 | D19: 2 | E19: =COUNTIF(gamesToAssign!F$2:'gamesToAssign'!F$51,A19) -> 1
A20: Ross, Connor | B20: 2122378 | C20: 1 | D20: 2 | E20: =COUNTIF(gamesToAssign!F$2:'gamesToAssign'!F$51,A20) -> 0 | F20: Massel, Jacob
A21: Bayntun, Liam | B21: 2122359 | C21: 14 | D21: 2 | E21: =COUNTIF(gamesToAssign!F$2:'gamesToAssign'!F$51,A21) -> 1
A22: MacDonald-Skala, Viggo | B22: 2122369 | C22: 18 | D22: 2 | E22: =COUNTIF(gamesToAssign!F$2:'gamesToAssign'!F$51,A22) -> 2
A23: Wong, Declan | B23: 2122642 | C23: 6 | D23: 2 | E23: =COUNTIF(gamesToAssign!F$2:'gamesToAssign'!F$51,A23) -> 0 | F23: Massel, Jacob, Pettersson, Oskar, Ozaki, Jin, Sato, Zain, Black, Brooks, Arai, Tatsuki
A24: Lee, Peyton | B24: 2112769 | C24: 1 | D24: 2 | E24: =COUNTIF(gamesToAssign!F$2:'gamesToAssign'!F$51,A24) -> 1
A25: Dolgin, Erez | B25: 2122362 | C25: 6 | D25: 2 | E25: =COUNTIF(gamesToAssign!F$2:'gamesToAssign'!F$51,A25) -> 2
A26: Rose, John | B26: 2122377 | C26: 4 | D26: 2 | E26: =COUNTIF(gamesToAssign!F$2:'gamesToAssign'!F$51,A26) -> 1
A27: Froelich, Ari | B27: 1018110 | C27: 2 | D27: 1 | E27: =COUNTIF(gamesToAssign!F$2:'gamesToAssign'!F$51,A27) -> 1
A28: Milton, Rigel | B28: 1899181 | C28: 1 | D28: 1 | E28: =COUNTIF(gamesToAssign!F$2:'gamesToAssign'!F$51,A28) -> 0 | F28: Massel, Jacob
A29: Forbes, Sid | B29: 1899167 | C29: 3 | D29: 1 | E29: =COUNTIF(gamesToAssign!F$2:'gamesToAssign'!F$51,A29) -> 1
A30: Black, Brooks | B30: 2088216 | C30: 2 | D30: 1 | E30: =COUNTIF(gamesToAssign!F$2:'gamesToAssign'!F$51,A30) -> 1
A31: Morrison, Oscar | B31: 2122372 | C31: 3 | D31: 1 | E31: =COUNTIF(gamesToAssign!F$2:'gamesToAssign'!F$51,A31) -> 1
A32: Ozaki, Jin | B32: 2122374 | C32: 1 | D32: 1 | E32: =COUNTIF(gamesToAssign!F$2:'gamesToAssign'!F$51,A32) -> 1
A33: Arai, Tatsuki | B33: 2122356 | C33: 6 | D33: 1 | E33: =COUNTIF(gamesToAssign!F$2:'gamesToAssign'!F$51,A33) -> 1
A34: Morris, George | B34: 2122371 | C34: 1 | D34: 1 | E34: =COUNTIF(gamesToAssign!F$2:'gamesToAssign'!F$51,A34) -> 0 | F34: Ozaki, Jin
A35: Jeffcoatt, Ryan | B35: 961549 | C35: 1 | D35: 1 | E35: =COUNTIF(gamesToAssign!F$2:'gamesToAssign'!F$51,A35) -> 1
A36: McCulloch, Oswyn | B36: 2122370 | C36: 3 | D36: 1 | E36: =COUNTIF(gamesToAssign!F$2:'gamesToAssign'!F$51,A36) -> 1
A37: Chuang, Kayden | B37: 2122361 | C37: 1 | D37: 1 | E37: =COUNTIF(gamesToAssign!F$2:'gamesToAssign'!F$51,A37) -> 0 | F37: Pettersson, Oskar
A38: Stebbings, Colin | B38: 2122381 | C38: 6 | D38: 1 | E38: =COUNTIF(gamesToAssign!F$2:'gamesToAssign'!F$51,A38) -> 1
A39: Bellefeuille, Nicholas | B39: 1899161 | C39: 3 | D39: 0 | E39: =COUNTIF(gamesToAssign!F$2:'gamesToAssign'!F$51,A39) -> 1
A40: Massel, Jacob | B40: 1020591 | C40: 1 | D40: 0 | E40: =COUNTIF(gamesToAssign!F$2:'gamesToAssign'!F$51,A40) -> 1
...
